<?xml version="1.0" encoding="utf-8"?>


<!-- =================================================================================== -->
<!-- |    @uthor Min Htet Han ( ROM Robotics )                                         | -->
<!-- |    ROS Simulation Online Course                                                 | -->
<!-- =================================================================================== -->

<robot
  name="mobile_robot">
  <link
    name="base_link">
    <inertial>
      <origin
        xyz="0 1.38777878078145E-17 0.051160641551097"
        rpy="0 0 0" />
      <mass
        value="5.66307829279757" />
      <inertia
        ixx="0.0222241816470158"
        ixy="1.71982458995108E-18"
        ixz="4.71600220102887E-19"
        iyy="0.0465826797680732"
        iyz="4.54535736654549E-19"
        izz="0.0633261951991863" />
    </inertial>
    <visual>
      <origin
        xyz="0 0 0"
        rpy="0 0 0" />
      <geometry>
        <mesh
          filename="package://ros_control/meshes/mobile_robot/base_link.STL" />
      </geometry>
      <material
        name="">
        <color
          rgba="1 1 1 0.3" />
      </material>
    </visual>
    <collision>
      <origin
        xyz="0 0 0"
        rpy="0 0 0" />
      <geometry>
        <mesh
          filename="package://ros_control/meshes/mobile_robot/base_link.STL" />
      </geometry>
    </collision>
  </link>
  <link
    name="front_left_wheel">
    <inertial>
      <origin
        xyz="-2.29816166097407E-14 8.32818073997002E-06 -1.99840144432528E-14"
        rpy="0 0 0" />
      <mass
        value="0.258483573203574" />
      <inertia
        ixx="0.000189262516241649"
        ixy="1.19131585881481E-16"
        ixz="-4.74543000838003E-16"
        iyy="0.000350721870329167"
        iyz="2.66946074577865E-16"
        izz="0.000189262516241838" />
    </inertial>
    <visual>
      <origin
        xyz="0 0 0"
        rpy="0 0 0" />
      <geometry>
        <mesh
          filename="package://ros_control/meshes/mobile_robot/front_left_wheel.STL" />
      </geometry>
      <material
        name="">
        <color
          rgba="1 1 1 0.3" />
      </material>
    </visual>
    <collision>
      <origin
        xyz="0 0 0"
        rpy="0 0 0" />
      <geometry>
        <mesh
          filename="package://ros_control/meshes/mobile_robot/front_left_wheel.STL" />
      </geometry>
    </collision>
  </link>
  <joint
    name="front_left_joint"
    type="continuous">
    <origin
      xyz="0.1016 0.1143 0.051160641551097"
      rpy="0 0 0" />
    <parent
      link="base_link" />
    <child
      link="front_left_wheel" />
    <axis
      xyz="0 1 0" />
    <safety_controller
      k_velocity="0" />
  </joint>
  <link
    name="front_right_wheel">
    <inertial>
      <origin
        xyz="1.47659662275146E-14 -8.32818073995267E-06 2.72559752545476E-14"
        rpy="0 0 0" />
      <mass
        value="0.258483573203574" />
      <inertia
        ixx="0.000189262516242037"
        ixy="2.3312284814222E-16"
        ixz="-3.94183401690999E-16"
        iyy="0.000350721870329169"
        iyz="1.76440825004407E-16"
        izz="0.000189262516241465" />
    </inertial>
    <visual>
      <origin
        xyz="0 0 0"
        rpy="0 0 0" />
      <geometry>
        <mesh
          filename="package://ros_control/meshes/mobile_robot/front_right_wheel.STL" />
      </geometry>
      <material
        name="">
        <color
          rgba="1 1 1 0.3" />
      </material>
    </visual>
    <collision>
      <origin
        xyz="0 0 0"
        rpy="0 0 0" />
      <geometry>
        <mesh
          filename="package://ros_control/meshes/mobile_robot/front_right_wheel.STL" />
      </geometry>
    </collision>
  </link>
  <joint
    name="front_right_joint"
    type="continuous">
    <origin
      xyz="0.1016 -0.1143 0.051160641551097"
      rpy="0 0 0" />
    <parent
      link="base_link" />
    <child
      link="front_right_wheel" />
    <axis
      xyz="0 1 0" />
    <safety_controller
      k_velocity="0" />
  </joint>
  <link
    name="back_right_wheel">
    <inertial>
      <origin
        xyz="2.02060590481778E-14 -8.32818074003594E-06 -2.16493489801906E-14"
        rpy="0 0 0" />
      <mass
        value="0.258483573203574" />
      <inertia
        ixx="0.000189262516241685"
        ixy="1.02584447394406E-16"
        ixz="4.9066877944318E-16"
        iyy="0.000350721870329138"
        iyz="-2.76945192048971E-16"
        izz="0.000189262516241772" />
    </inertial>
    <visual>
      <origin
        xyz="0 0 0"
        rpy="0 0 0" />
      <geometry>
        <mesh
          filename="package://ros_control/meshes/mobile_robot/back_right_wheel.STL" />
      </geometry>
      <material
        name="">
        <color
          rgba="1 1 1 0.3" />
      </material>
    </visual>
    <collision>
      <origin
        xyz="0 0 0"
        rpy="0 0 0" />
      <geometry>
        <mesh
          filename="package://ros_control/meshes/mobile_robot/back_right_wheel.STL" />
      </geometry>
    </collision>
  </link>
  <joint
    name="back_right_joint"
    type="continuous">
    <origin
      xyz="-0.1016 -0.1143 0.051160641551097"
      rpy="0 0 0" />
    <parent
      link="base_link" />
    <child
      link="back_right_wheel" />
    <axis
      xyz="0 1 0" />
    <safety_controller
      k_velocity="0.2" />
  </joint>
  <link
    name="back_left_wheel">
    <inertial>
      <origin
        xyz="-1.50990331349021E-14 8.32818074007931E-06 -2.63122856836162E-14"
        rpy="0 0 0" />
      <mass
        value="0.258483573203575" />
      <inertia
        ixx="0.000189262516241906"
        ixy="4.1157050314185E-17"
        ixz="-4.70201546785752E-16"
        iyy="0.000350721870329123"
        iyz="2.94676610981564E-16"
        izz="0.00018926251624155" />
    </inertial>
    <visual>
      <origin
        xyz="0 0 0"
        rpy="0 0 0" />
      <geometry>
        <mesh
          filename="package://ros_control/meshes/mobile_robot/back_left_wheel.STL" />
      </geometry>
      <material
        name="">
        <color
          rgba="1 1 1 0.3" />
      </material>
    </visual>
    <collision>
      <origin
        xyz="0 0 0"
        rpy="0 0 0" />
      <geometry>
        <mesh
          filename="package://ros_control/meshes/mobile_robot/back_left_wheel.STL" />
      </geometry>
    </collision>
  </link>
  <joint
    name="back_left_joint"
    type="continuous">
    <origin
      xyz="-0.1016 0.1143 0.051160641551097"
      rpy="0 0 0" />
    <parent
      link="base_link" />
    <child
      link="back_left_wheel" />
    <axis
      xyz="0 1 0" />
    <safety_controller
      k_velocity="0" />
  </joint>

   <transmission name="front_right_wheel">
    <type>transmission_interface/SimpleTransmission</type>
      <joint name="front_right_joint">
    
      <hardwareInterface>hardware_interface/VelocityJointInterface</hardwareInterface>
    </joint>
    <actuator name="front_right_motor">
      
      <hardwareInterface>hardware_interface/VelocityJointInterface</hardwareInterface>
      <mechanicalReduction>1</mechanicalReduction>
    </actuator>
  </transmission>

    <transmission name="front_left_wheel">
    <type>transmission_interface/SimpleTransmission</type>
      <joint name="front_left_joint">

      <hardwareInterface>hardware_interface/VelocityJointInterface</hardwareInterface>
    </joint>
    <actuator name="front_left_motor">

      <hardwareInterface>hardware_interface/VelocityJointInterface</hardwareInterface>
      <mechanicalReduction>1</mechanicalReduction>
    </actuator>
  </transmission>

     <transmission name="back_left_wheel">
  <type>transmission_interface/SimpleTransmission</type>
      <joint name="back_left_joint">

      <hardwareInterface>hardware_interface/VelocityJointInterface</hardwareInterface>
    </joint>
    <actuator name="back_left_motor">
  
      <hardwareInterface>hardware_interface/VelocityJointInterface</hardwareInterface>
      <mechanicalReduction>1</mechanicalReduction>
    </actuator>
  </transmission>

  <transmission name="back_right_wheel">
    <type>transmission_interface/SimpleTransmission</type>
      <joint name="back_right_joint">
 
      <hardwareInterface>hardware_interface/VelocityJointInterface</hardwareInterface>
    </joint>
    <actuator name="back_right_motor">
      
      <hardwareInterface>hardware_interface/VelocityJointInterface</hardwareInterface>
      <mechanicalReduction>1</mechanicalReduction>
    </actuator>
  </transmission>

  <gazebo>
  <plugin name="gazebo_ros_control" filename="libgazebo_ros_control.so">
    
  </plugin>
</gazebo> 

  <link name="imu_link">
    <visual>
      <origin rpy="0 0 0" xyz="0 0 0"/>
      <geometry>
        <box size="0.02 0.02 0.01"/>
      </geometry>
    </visual>

    <collision>
      <origin rpy="0 0 0" xyz="0 0 0"/>
      <geometry>
        <box size="0.02 0.02 0.01"/>
      </geometry>
    </collision>
    <inertial>
      <origin
        xyz="-1.1631E-07 4.6695E-06 0.49998"
        rpy="0 0 0" />
      <mass
        value="0.28" />
      <inertia
        ixx="4.1595"
        ixy="-5.4696E-07"
        ixz="2.4978E-06"
        iyy="4.1595"
        iyz="-0.00010027"
        izz="0.31998" />
    </inertial>   
  </link>
  
  <joint name="link_one_to_link_two" type="fixed">
    <origin rpy="0 0 0" xyz = "0 0 0.10"/>
    <parent link="base_link"/>
    <child link="imu_link"/>
    <axis xyz="0 0 0"/>
  </joint>

<gazebo>
  <plugin name="imu_plugin" filename="libgazebo_ros_imu.so">
    <alwaysOn>true</alwaysOn>
    <updateRate>100.0</updateRate> 
    <bodyName>imu_link</bodyName>
    <topicName>imu_data</topicName>
    <gaussianNoise>1e-06</gaussianNoise>
   </plugin>
</gazebo>   

 
<!--gazebo>
  <plugin name="skid_steer_drive_controller" filename="libgazebo_ros_skid_steer_drive.so">
    <updateRate>100.0</updateRate>
    <robotNamespace>/</robotNamespace>
    <leftFrontJoint>front_left_joint</leftFrontJoint>
    <rightFrontJoint>front_right_joint</rightFrontJoint>
    <leftRearJoint>back_left_joint</leftRearJoint>
    <rightRearJoint>back_right_joint</rightRearJoint>
    <wheelSeparation>0.2032</wheelSeparation>
    <wheelDiameter>0.1016</wheelDiameter>
    <robotBaseFrame>base_link</robotBaseFrame>
    <torque>100</torque>
    <topicName>cmd_vel</topicName>
    <broadcastTF>false</broadcastTF>
  </plugin>
</gazebo-->

</robot>
